[2025-03-26T06:15:18.056+0000] {local_task_job_runner.py:123} INFO - ::group::Pre task execution logs
[2025-03-26T06:15:18.062+0000] {taskinstance.py:2612} INFO - Dependencies all met for dep_context=non-requeueable deps ti=<TaskInstance: import_user_session_data.load_user_session_channel manual__2025-03-26T06:15:16.804886+00:00 [queued]>
[2025-03-26T06:15:18.066+0000] {taskinstance.py:2612} INFO - Dependencies all met for dep_context=requeueable deps ti=<TaskInstance: import_user_session_data.load_user_session_channel manual__2025-03-26T06:15:16.804886+00:00 [queued]>
[2025-03-26T06:15:18.067+0000] {taskinstance.py:2865} INFO - Starting attempt 1 of 1
[2025-03-26T06:15:18.073+0000] {taskinstance.py:2888} INFO - Executing <Task(_PythonDecoratedOperator): load_user_session_channel> on 2025-03-26 06:15:16.804886+00:00
[2025-03-26T06:15:18.077+0000] {logging_mixin.py:190} WARNING - /home/***/.local/lib/python3.12/site-packages/***/task/task_runner/standard_task_runner.py:70 DeprecationWarning: This process (pid=258) is multi-threaded, use of fork() may lead to deadlocks in the child.
[2025-03-26T06:15:18.077+0000] {standard_task_runner.py:72} INFO - Started process 264 to run task
[2025-03-26T06:15:18.077+0000] {standard_task_runner.py:104} INFO - Running: ['***', 'tasks', 'run', 'import_user_session_data', 'load_user_session_channel', 'manual__2025-03-26T06:15:16.804886+00:00', '--job-id', '2', '--raw', '--subdir', 'DAGS_FOLDER/import_user_session_data.py', '--cfg-path', '/tmp/tmpgqt6xk4g']
[2025-03-26T06:15:18.078+0000] {standard_task_runner.py:105} INFO - Job 2: Subtask load_user_session_channel
[2025-03-26T06:15:18.100+0000] {task_command.py:467} INFO - Running <TaskInstance: import_user_session_data.load_user_session_channel manual__2025-03-26T06:15:16.804886+00:00 [running]> on host 2b6f10f8412e
[2025-03-26T06:15:18.129+0000] {taskinstance.py:3131} INFO - Exporting env vars: AIRFLOW_CTX_DAG_OWNER='***' AIRFLOW_CTX_DAG_ID='import_user_session_data' AIRFLOW_CTX_TASK_ID='load_user_session_channel' AIRFLOW_CTX_EXECUTION_DATE='2025-03-26T06:15:16.804886+00:00' AIRFLOW_CTX_TRY_NUMBER='1' AIRFLOW_CTX_DAG_RUN_ID='manual__2025-03-26T06:15:16.804886+00:00'
[2025-03-26T06:15:18.130+0000] {taskinstance.py:731} INFO - ::endgroup::
[2025-03-26T06:15:18.138+0000] {taskinstance.py:3310} ERROR - Task failed with exception
Traceback (most recent call last):
  File "/home/airflow/.local/lib/python3.12/site-packages/airflow/models/taskinstance.py", line 767, in _execute_task
    result = _execute_callable(context=context, **execute_callable_kwargs)
             ^^^^^^^^^^^^^^^^^^^^^^^^^^^^^^^^^^^^^^^^^^^^^^^^^^^^^^^^^^^^^
  File "/home/airflow/.local/lib/python3.12/site-packages/airflow/models/taskinstance.py", line 733, in _execute_callable
    return ExecutionCallableRunner(
           ^^^^^^^^^^^^^^^^^^^^^^^^
  File "/home/airflow/.local/lib/python3.12/site-packages/airflow/utils/operator_helpers.py", line 252, in run
    return self.func(*args, **kwargs)
           ^^^^^^^^^^^^^^^^^^^^^^^^^^
  File "/home/airflow/.local/lib/python3.12/site-packages/airflow/models/baseoperator.py", line 406, in wrapper
    return func(self, *args, **kwargs)
           ^^^^^^^^^^^^^^^^^^^^^^^^^^^
  File "/home/airflow/.local/lib/python3.12/site-packages/airflow/decorators/base.py", line 266, in execute
    return_value = super().execute(context)
                   ^^^^^^^^^^^^^^^^^^^^^^^^
  File "/home/airflow/.local/lib/python3.12/site-packages/airflow/models/baseoperator.py", line 406, in wrapper
    return func(self, *args, **kwargs)
           ^^^^^^^^^^^^^^^^^^^^^^^^^^^
  File "/home/airflow/.local/lib/python3.12/site-packages/airflow/operators/python.py", line 238, in execute
    return_value = self.execute_callable()
                   ^^^^^^^^^^^^^^^^^^^^^^^
  File "/home/airflow/.local/lib/python3.12/site-packages/airflow/operators/python.py", line 256, in execute_callable
    return runner.run(*self.op_args, **self.op_kwargs)
           ^^^^^^^^^^^^^^^^^^^^^^^^^^^^^^^^^^^^^^^^^^^
  File "/home/airflow/.local/lib/python3.12/site-packages/airflow/utils/operator_helpers.py", line 252, in run
    return self.func(*args, **kwargs)
           ^^^^^^^^^^^^^^^^^^^^^^^^^^
  File "/opt/airflow/dags/import_user_session_data.py", line 20, in load_user_session_channel
    cur = return_snowflake_conn()
          ^^^^^^^^^^^^^^^^^^^^^^^
  File "/opt/airflow/dags/import_user_session_data.py", line 15, in return_snowflake_conn
    return hook.get_conn().cursor()
           ^^^^^^^^^^^^^^^
  File "/home/airflow/.local/lib/python3.12/site-packages/airflow/providers/snowflake/hooks/snowflake.py", line 299, in get_conn
    conn_config = self._get_conn_params
                  ^^^^^^^^^^^^^^^^^^^^^
  File "/usr/local/lib/python3.12/functools.py", line 993, in __get__
    val = self.func(instance)
          ^^^^^^^^^^^^^^^^^^^
  File "/home/airflow/.local/lib/python3.12/site-packages/airflow/providers/snowflake/hooks/snowflake.py", line 192, in _get_conn_params
    conn = self.get_connection(self.snowflake_conn_id)  # type: ignore[attr-defined]
           ^^^^^^^^^^^^^^^^^^^^^^^^^^^^^^^^^^^^^^^^^^^
  File "/home/airflow/.local/lib/python3.12/site-packages/airflow/hooks/base.py", line 83, in get_connection
    conn = Connection.get_connection_from_secrets(conn_id)
           ^^^^^^^^^^^^^^^^^^^^^^^^^^^^^^^^^^^^^^^^^^^^^^^
  File "/home/airflow/.local/lib/python3.12/site-packages/airflow/models/connection.py", line 537, in get_connection_from_secrets
    raise AirflowNotFoundException(f"The conn_id `{conn_id}` isn't defined")
airflow.exceptions.AirflowNotFoundException: The conn_id `snowflake_conn` isn't defined
[2025-03-26T06:15:18.141+0000] {taskinstance.py:1225} INFO - Marking task as FAILED. dag_id=import_user_session_data, task_id=load_user_session_channel, run_id=manual__2025-03-26T06:15:16.804886+00:00, execution_date=20250326T061516, start_date=20250326T061518, end_date=20250326T061518
[2025-03-26T06:15:18.145+0000] {taskinstance.py:340} INFO - ::group::Post task execution logs
[2025-03-26T06:15:18.145+0000] {standard_task_runner.py:124} ERROR - Failed to execute job 2 for task load_user_session_channel (The conn_id `snowflake_conn` isn't defined; 264)
Traceback (most recent call last):
  File "/home/airflow/.local/lib/python3.12/site-packages/airflow/task/task_runner/standard_task_runner.py", line 117, in _start_by_fork
    ret = args.func(args, dag=self.dag)
          ^^^^^^^^^^^^^^^^^^^^^^^^^^^^^
  File "/home/airflow/.local/lib/python3.12/site-packages/airflow/cli/cli_config.py", line 49, in command
    return func(*args, **kwargs)
           ^^^^^^^^^^^^^^^^^^^^^
  File "/home/airflow/.local/lib/python3.12/site-packages/airflow/utils/cli.py", line 115, in wrapper
    return f(*args, **kwargs)
           ^^^^^^^^^^^^^^^^^^
  File "/home/airflow/.local/lib/python3.12/site-packages/airflow/cli/commands/task_command.py", line 483, in task_run
    task_return_code = _run_task_by_selected_method(args, _dag, ti)
                       ^^^^^^^^^^^^^^^^^^^^^^^^^^^^^^^^^^^^^^^^^^^^
  File "/home/airflow/.local/lib/python3.12/site-packages/airflow/cli/commands/task_command.py", line 256, in _run_task_by_selected_method
    return _run_raw_task(args, ti)
           ^^^^^^^^^^^^^^^^^^^^^^^
  File "/home/airflow/.local/lib/python3.12/site-packages/airflow/cli/commands/task_command.py", line 341, in _run_raw_task
    return ti._run_raw_task(
           ^^^^^^^^^^^^^^^^^
  File "/home/airflow/.local/lib/python3.12/site-packages/airflow/utils/session.py", line 97, in wrapper
    return func(*args, session=session, **kwargs)
           ^^^^^^^^^^^^^^^^^^^^^^^^^^^^^^^^^^^^^^
  File "/home/airflow/.local/lib/python3.12/site-packages/airflow/models/taskinstance.py", line 3004, in _run_raw_task
    return _run_raw_task(
           ^^^^^^^^^^^^^^
  File "/home/airflow/.local/lib/python3.12/site-packages/airflow/models/taskinstance.py", line 273, in _run_raw_task
    TaskInstance._execute_task_with_callbacks(
  File "/home/airflow/.local/lib/python3.12/site-packages/airflow/models/taskinstance.py", line 3158, in _execute_task_with_callbacks
    result = self._execute_task(context, task_orig)
             ^^^^^^^^^^^^^^^^^^^^^^^^^^^^^^^^^^^^^^
  File "/home/airflow/.local/lib/python3.12/site-packages/airflow/models/taskinstance.py", line 3182, in _execute_task
    return _execute_task(self, context, task_orig)
           ^^^^^^^^^^^^^^^^^^^^^^^^^^^^^^^^^^^^^^^
  File "/home/airflow/.local/lib/python3.12/site-packages/airflow/models/taskinstance.py", line 767, in _execute_task
    result = _execute_callable(context=context, **execute_callable_kwargs)
             ^^^^^^^^^^^^^^^^^^^^^^^^^^^^^^^^^^^^^^^^^^^^^^^^^^^^^^^^^^^^^
  File "/home/airflow/.local/lib/python3.12/site-packages/airflow/models/taskinstance.py", line 733, in _execute_callable
    return ExecutionCallableRunner(
           ^^^^^^^^^^^^^^^^^^^^^^^^
  File "/home/airflow/.local/lib/python3.12/site-packages/airflow/utils/operator_helpers.py", line 252, in run
    return self.func(*args, **kwargs)
           ^^^^^^^^^^^^^^^^^^^^^^^^^^
  File "/home/airflow/.local/lib/python3.12/site-packages/airflow/models/baseoperator.py", line 406, in wrapper
    return func(self, *args, **kwargs)
           ^^^^^^^^^^^^^^^^^^^^^^^^^^^
  File "/home/airflow/.local/lib/python3.12/site-packages/airflow/decorators/base.py", line 266, in execute
    return_value = super().execute(context)
                   ^^^^^^^^^^^^^^^^^^^^^^^^
  File "/home/airflow/.local/lib/python3.12/site-packages/airflow/models/baseoperator.py", line 406, in wrapper
    return func(self, *args, **kwargs)
           ^^^^^^^^^^^^^^^^^^^^^^^^^^^
  File "/home/airflow/.local/lib/python3.12/site-packages/airflow/operators/python.py", line 238, in execute
    return_value = self.execute_callable()
                   ^^^^^^^^^^^^^^^^^^^^^^^
  File "/home/airflow/.local/lib/python3.12/site-packages/airflow/operators/python.py", line 256, in execute_callable
    return runner.run(*self.op_args, **self.op_kwargs)
           ^^^^^^^^^^^^^^^^^^^^^^^^^^^^^^^^^^^^^^^^^^^
  File "/home/airflow/.local/lib/python3.12/site-packages/airflow/utils/operator_helpers.py", line 252, in run
    return self.func(*args, **kwargs)
           ^^^^^^^^^^^^^^^^^^^^^^^^^^
  File "/opt/airflow/dags/import_user_session_data.py", line 20, in load_user_session_channel
    cur = return_snowflake_conn()
          ^^^^^^^^^^^^^^^^^^^^^^^
  File "/opt/airflow/dags/import_user_session_data.py", line 15, in return_snowflake_conn
    return hook.get_conn().cursor()
           ^^^^^^^^^^^^^^^
  File "/home/airflow/.local/lib/python3.12/site-packages/airflow/providers/snowflake/hooks/snowflake.py", line 299, in get_conn
    conn_config = self._get_conn_params
                  ^^^^^^^^^^^^^^^^^^^^^
  File "/usr/local/lib/python3.12/functools.py", line 993, in __get__
    val = self.func(instance)
          ^^^^^^^^^^^^^^^^^^^
  File "/home/airflow/.local/lib/python3.12/site-packages/airflow/providers/snowflake/hooks/snowflake.py", line 192, in _get_conn_params
    conn = self.get_connection(self.snowflake_conn_id)  # type: ignore[attr-defined]
           ^^^^^^^^^^^^^^^^^^^^^^^^^^^^^^^^^^^^^^^^^^^
  File "/home/airflow/.local/lib/python3.12/site-packages/airflow/hooks/base.py", line 83, in get_connection
    conn = Connection.get_connection_from_secrets(conn_id)
           ^^^^^^^^^^^^^^^^^^^^^^^^^^^^^^^^^^^^^^^^^^^^^^^
  File "/home/airflow/.local/lib/python3.12/site-packages/airflow/models/connection.py", line 537, in get_connection_from_secrets
    raise AirflowNotFoundException(f"The conn_id `{conn_id}` isn't defined")
airflow.exceptions.AirflowNotFoundException: The conn_id `snowflake_conn` isn't defined
[2025-03-26T06:15:18.176+0000] {local_task_job_runner.py:266} INFO - Task exited with return code 1
[2025-03-26T06:15:18.185+0000] {taskinstance.py:3900} INFO - 0 downstream tasks scheduled from follow-on schedule check
[2025-03-26T06:15:18.186+0000] {local_task_job_runner.py:245} INFO - ::endgroup::
